Workbook

Sheet Read Me
A1: Nifty 500 AI signals - daily run for Fri 23-Oct-2026
A2: NSE data to the close of Fri 23-Oct-2026. Market regime: FALLING (Nifty 50 below its 50- and 200-DMA). Breadth: 10% of Nifty 500 stocks above their 50-DMA, 27% above their 200-DMA.
A3: Research output for paper trading and education - not investment advice; not a SEBI-registered adviser. Every probability is a historical frequency, not a promise.
A4: Track record of these daily calls: 34% of 406 completed calls were right (since 2026-09-25); days whose calls have all finished: 39% of 348. Full detail on the last sheet, 'Success Rate'.
A6: Today's calls in one line per timeframe
A7: • Short term (up to 2 weeks): 29 buy calls (20 Strong Buy), 74 avoid/reduce, the rest hold.
A8: • Mid term (up to 3 months): 1 buy calls (0 Strong Buy), 81 avoid/reduce, the rest hold.
A9: • Long term (up to 1 year): 2 buy calls (0 Strong Buy), 121 avoid/reduce, the rest hold.
A11: What goes into every run
A12: • 454 indicator values per stock per day: the complete TA-Lib library (136 functions) plus 60+ tools it lacks - Ichimoku, Supertrend, Renko, Kagi, three-line break, Heikin-Ashi, point & figure, volume profile, anchored VWAPs, pivot points, Laguerre/Connors RSI, Fisher, Schaff, KST, Klinger, Hurst, NSE delivery-% analytics, relative strength vs Nifty and sector, market breadth, calendar effects. Every value uses only past data.
A13: • 137 chart-pattern types found by a swing engine at three swing sizes: head & shoulders, double/triple tops & bottoms, cup & handle, triangles, wedges, flags, pennants, rectangles, channels, broadening formations, diamonds, rounding tops/bottoms, V-reversals, islands, gaps, Darvas boxes, VCP, flat bases, high-tight flags, Wyckoff springs/upthrusts, 2B/turtle soup, Dow-theory reversals, Elliott 5-wave counts, three drives, harmonics (Gartley, Bat, Butterfly, Crab, Deep crab, Cypher, AB=CD), Wolfe waves, Quasimodo, Fibonacci pull-backs, trendline and support/resistance breaks, divergences, pipes & horns, point & figure signals.
A14: • 104 classic indicator signals and 177 candlestick signals (all 61 TA-Lib patterns, raw and in trend context, plus tweezers, pin bars, outside bars).
... A28: Trade rules per timeframe (levels are multiples of the 14-day ATR, the stock's average daily range)
A29: Timeframe | B29: Stop (x ATR) | C29: Target (x ATR) | D29: No-chase (x ATR) | E29: Max days | F29: Reward : risk | G29: Notes
A30: Short term (up to 2 weeks) | B30: 1.5 | C30: 3 | D30: 1 | E30: 10 | F30: =C30/B30 | G30: Blue cells are inputs: change them and every Entry/Target/Stop on 'Signals' recalculates. The success-rate tracker always uses the published levels.
A31: Mid term (up to 3 months) | B31: 3 | C31: 6 | D31: 1.5 | E31: 60 | F31: =C31/B31 | G31: Blue cells are inputs: change them and every Entry/Target/Stop on 'Signals' recalculates. The success-rate tracker always uses the published levels.
A32: Long term (up to 1 year) | B32: 5 | C32: 10 | D32: 2 | E32: 250 | F32: =C32/B32 | G32: Blue cells are inputs: change them and every Entry/Target/Stop on 'Signals' recalculates. The success-rate tracker always uses the published levels.
A34: What the research evidence says (read before trading)
A35: • Short term is where the model is most reliable: its daily ranking beat chance in 7 of 7 years (rank correlation 0.036); the top 5% beat the same-day average stock by +0.33% per 2-week trade overall and +0.14% in falling markets. Small per trade - costs and discipline matter.
A36: • Mid and long term: the model's buy ranking did NOT beat the average stock in falling markets (its favourites lagged, beaten-down stocks rebounded more), so mid/long-term buys today come only from proven setups. Its warnings (likely underperformers) held up in rising, mixed and falling markets and in 19 of 20 test years across the three horizons - the most dependable output.
A37: • Chart patterns alone: only 2 of 137 pattern types beat the average stock reliably over 3 months (Fibonacci 38-62% rally failure in a downtrend, Wyckoff upthrust - both bearish warnings); 14 worked in reverse; 'buy after a crash' looked like a winner but was a survivorship illusion (below). Textbook patterns did not beat the average stock on NSE in 2017-26: double bottom (t -2.2), symmetrical-triangle breakout (t -2.2), ascending-triangle breakout (t -0.5), bull flag (t -0.3), cup breakout (t +0.0), head & shoulders top (t -0.1); inverse head & shoulders (t -3.4) and Wyckoff springs (t -4.8) did reliably worse than average (3-month t-stats; |t| >= 3 needed).
A38: • What did work: buying orderly pullbacks inside strong uptrends (Holy Grail, three lower closes, RSI(2) < 5; IBS < 0.2 and Double 7s too, with smaller effects), stocks whose relative-strength line makes a 52-week high or whose moving averages newly stack bullish, and avoiding stocks in stage-4 downtrends or with RSI(2) > 95 in a downtrend. Late trend-following buy flips (Supertrend, Parabolic SAR, volatility stop, Renko/three-line-break reversals, 20-day breakouts) tended to underperform afterwards.
A39: • Survivorship check on the full NSE universe as it stood each day: an average 3-month trade hit target 28% vs 30% on today's constituents; 1-year 38% vs 43%. All long-side confidences here are corrected for this.
A40: • 'Buy after a 15% two-day crash' looked great on today's list (+7.4% vs average over a year) but not on the full universe (median -14.7%; 57% of such crashes were in stocks that later left the index) - so it is NOT used as a buy reason.
A42: Market on Fri 23-Oct-2026 (computed from NSE data)
A43: • Nifty 50 closed at 22,600.00 (-0.39% on the day, -3.1% over one month, -12.1% over one year); -3.4% from its 50-DMA and -6.3% from its 200-DMA.
A44: • Breadth: 10% of Nifty 500 stocks above their 50-DMA (-5 pts in 10 sessions) and 27% above their 200-DMA; 8% of stocks rose on the day; 52-week highs minus lows: -20.8% of stocks.
A45: • Mid caps (Nifty Midcap 150) vs Nifty 50 over one month: -6.5 pts; small caps (Nifty Smallcap 250): -7.1 pts.
A47: Data checks for this run
... A51: Data: NSE bhavcopy and index closes (nsearchives.nseindia.com; GitHub mirrors tilak999/NSE-Data-bank and Chaudharyrohit2506/nse-daily-ohlcv as fallback), history from kaushikghoshindia/NSE500Tracker. Splits, bonuses and demergers are adjusted automatically from NSE's adjusted previous close. Research tool - not investment advice.

Sheet Signals
A1: Symbol | B1: Company | C1: Sector | D1: Timeframe | E1: AI recommendation | F1: Recommendation type | G1: AI confidence - buy side | H1: AI confidence - short side | I1: Chance of profit (recommended side) | J1: Expected return per trade | K1: Edge vs average stock | L1: Current price Rs | M1: ATR 14 Rs | N1: Entry Rs (buy up to) | O1: Target Rs (sell at) | P1: Stop loss Rs | Q1: Potential profit | R1: Potential loss | S1: Days to hold (max) | T1: Typical days to target | U1: Current trend | V1: Evidence (AI model rank + proven signals) | W1: Active chart patterns (last 10 sessions) [3-mth verdict] | X1: Latest results check | Y1: Remarks
A2: KOTAKBANK | B2: Kotak Mahindra Bank Ltd. | C2: Financial Services | D2: Short term (up to 2 weeks) | E2: Buy | F2: Buy | G2: 0.17817111 | H2: 0.14315289 | I2: 0.43614344 | J2: 0.0054175239 | K2: 2.4210056 | L2: 430.5 | M2: 9.5389728 | N2: =ROUND(L2+'Read Me'!$D$30*M2,2) | O2: =ROUND(L2+'Read Me'!$C$30*M2,2) | P2: =ROUND(L2-'Read Me'!$B$30*M2,2) | Q2: =ABS(O2-L2)/L2 | R2: =ABS(L2-P2)/L2 | S2: 10 | T2: 6 | U2: Sideways | V2: Model rank: top 34% buy side / top 15% short side (buy bucket: 50-70%); + Holy Grail: ADX > 30 and pullback to 20 EMA (23-Oct): +0.4% vs avg stock, t 4.6; + RSI(2) below 5 in an uptrend (Connors) (23-Oct): +0.2% vs avg stock, t 3.6 | W2: ▼ 2B top / Turtle soup 19-Oct [weak edge]; ▼ Bearish AB=CD 19-Oct [no edge]; ▼ Wyckoff upthrust 16-Oct [works]; ▲ Pocket pivot 15-Oct [no edge] | X2: Supportive | Y2: Proven setup active: Holy Grail: ADX > 30 and pullback to 20 EMA (23-Oct) - historically +0.4% vs the average stock over 2 weeks (t 4.6, also positive in falling markets). Buy confidence 18% vs 15% for an average stock; expected +0.5% per trade after costs. Technicals: RSI 52; RS rating 82; -5% from 52-wk high; below 20-EMA. Results Q1 FY27 (Apr-Jun 2026) - revenue: NII +9%; profit: Standalone +26% to Rs 4,123 Cr; consolidated +23% to Rs 5,480 Cr (supportive).
A3: KOTAKBANK | B3: Kotak Mahindra Bank Ltd. | C3: Financial Services | D3: Mid term (up to 3 months) | E3: Buy | F3: Buy | G3: 0.31279249 | H3: 0.12952211 | I3: 0.50460817 | J3: 0.054241333 | K3: 3.8472033 | L3: 430.5 | M3: 9.5389728 | N3: =ROUND(L3+'Read Me'!$D$31*M3,2) | O3: =ROUND(L3+'Read Me'!$C$31*M3,2) | P3: =ROUND(L3-'Read Me'!$B$31*M3,2) | Q3: =ABS(O3-L3)/L3 | R3: =ABS(L3-P3)/L3 | S3: 60 | T3: 29 | U3: Up | V3: Model rank: top 18% buy side / top 27% short side (buy bucket: 70-85%); + Holy Grail: ADX > 30 and pullback to 20 EMA (23-Oct): +1.3% vs avg stock, t 6.1; + Three lower closes in an uptrend (21-Oct): +0.5% vs avg stock, t 6.7 | W3: ▼ 2B top / Turtle soup 19-Oct [weak edge]; ▼ Bearish AB=CD 19-Oct [no edge]; ▼ Wyckoff upthrust 16-Oct [works]; ▲ Pocket pivot 15-Oct [no edge] | X3: Supportive | Y3: Proven setup active: Holy Grail: ADX > 30 and pullback to 20 EMA (23-Oct) - historically +1.3% vs the average stock over 3 months (t 6.1, also positive in falling markets). Buy confidence 31% vs 27% for an average stock; expected +5.4% per trade after costs. Technicals: RSI 52; RS rating 82; -5% from 52-wk high; above a rising 50-DMA. Results Q1 FY27 (Apr-Jun 2026) - revenue: NII +9%; profit: Standalone +26% to Rs 4,123 Cr; consolidated +23% to Rs 5,480 Cr (supportive).
A4: KOTAKBANK | B4: Kotak Mahindra Bank Ltd. | C4: Financial Services | D4: Long term (up to 1 year) | E4: Accumulate | F4: Accumulate (buy on dips) | G4: 0.39511908 | H4: 0.085280983 | I4: 0.5305555 | J4: 0.15576886 | K4: 1.9765596 | L4: 430.5 | M4: 9.5389728 | N4: =ROUND(L4+'Read Me'!$D$32*M4,2) | O4: =ROUND(L4+'Read Me'!$C$32*M4,2) | P4: =ROUND(L4-'Read Me'!$B$32*M4,2) | Q4: =ABS(O4-L4)/L4 | R4: =ABS(L4-P4)/L4 | S4: 250 | T4: 86 | U4: Sideways | V4: Model rank: top 9% buy side / top 25% short side (buy bucket: Top 15% (85-95%)); + Holy Grail: ADX > 30 and pullback to 20 EMA (23-Oct): +3.1% vs avg stock, t 6.4; + Three lower closes in an uptrend (21-Oct): +1.8% vs avg stock, t 6.9 | W4: ▼ 2B top / Turtle soup 19-Oct [weak edge]; ▼ Bearish AB=CD 19-Oct [no edge]; ▼ Wyckoff upthrust 16-Oct [works]; ▲ Pocket pivot 15-Oct [no edge] | X4: Supportive | Y4: Proven setup active: Holy Grail: ADX > 30 and pullback to 20 EMA (23-Oct) - historically +3.1% vs the average stock over 1 year (t 6.4, also positive in falling markets). Buy confidence 40% vs 38% for an average stock; expected +15.6% per trade after costs. Build the position in parts on dips toward the 20/50-DMA rather than all at once. Technicals: RSI 52; RS rating 82; -5% from 52-wk high; above a falling 200-DMA. Results Q1 FY27 (Apr-Jun 2026) - revenue: NII +9%; profit: Standalone +26% to Rs 4,123 Cr; consolidated +23% to Rs 5,480 Cr (supportive).
A5: JWL | B5: Jupiter Wagons Ltd. | C5: Industrial Manufacturing | D5: Short term (up to 2 weeks) | E5: Buy | F5: Strong Buy | G5: 0.21183931 | H5: 0.084306981 | I5: 0.42819519 | J5: 0.0018773479 | K5: 5.7878251 | L5: 173.39 | M5: 8.4435707 | N5: =ROUND(L5+'Read Me'!$D$30*M5,2) | O5: =ROUND(L5+'Read Me'!$C$30*M5,2) | P5: =ROUND(L5-'Read Me'!$B$30*M5,2) | Q5: =ABS(O5-L5)/L5 | R5: =ABS(L5-P5)/L5 | S5: 10 | T5: 6 | U5: Down | V5: Model rank: top 1% buy side / bottom 7% short side (buy bucket: Top 5%) | W5: ▼ Descending broadening wedge - down breakout 14-Oct [no edge]; ▼ Falling wedge - down breakout 09-Oct [no edge] | X5: Not checked | Y5: AI model ranks it in the top 1% of stocks for a 2-week buy. Historically, top-5% names hit the target 21% of the time vs 15% for the average stock (weighted to falling markets like now), averaging +0.2% per trade after costs. Technicals: RSI 19; RS rating 1; -52% from 52-wk high; below 20-EMA.
A6: JWL | B6: Jupiter Wagons Ltd. | C6: Industrial Manufacturing | D6: Mid term (up to 3 months) | E6: Hold | F6: Hold / No fresh trade | G6: 0.29501647 | H6: 0.099596779 | I6: 0.49617973 | J6: 0.039061651 | K6: 2.0696017 | L6: 173.39 | M6: 8.4435707 | U6: Down | V6: Model rank: top 5% buy side / bottom 28% short side (buy bucket: Top 15% (85-95%)) | W6: ▼ Descending broadening wedge - down breakout 14-Oct [no edge]; ▼ Falling wedge - down breakout 09-Oct [no edge] | X6: Not checked | Y6: The model ranks it in the top 5% for a 3-month buy, but at this horizon its top ranks have not beaten the average stock in falling markets, so that is not counted; no proven signal active. Holders can keep; no fresh entry. Technicals: RSI 19; RS rating 1; -52% from 52-wk high; below a falling 50-DMA.
A7: JWL | B7: Jupiter Wagons Ltd. | C7: Industrial Manufacturing | D7: Long term (up to 1 year) | E7: Hold | F7: Hold / No fresh trade | G7: 0.35529798 | H7: 0.037138628 | I7: 0.51111196 | J7: 0.10959171 | K7: -2.00555 | L7: 173.39 | M7: 8.4435707 | U7: Down | V7: Model rank: top 43% buy side / bottom 8% short side (buy bucket: 50-70%); - RSI(14) rises back above 30 - fades (16-Oct): -1.6% vs avg stock, t 4.1 | W7: ▼ Descending broadening wedge - down breakout 14-Oct [no edge]; ▼ Falling wedge - down breakout 09-Oct [no edge] | X7: Not checked | Y7: No edge either way for 1 year (buy-side model rank: 57th percentile; no proven signal active). Holders can keep; no fresh entry. Technicals: RSI 19; RS rating 1; -52% from 52-wk high; below a falling 200-DMA.
A8: JBMA | B8: JBM Auto Ltd. | C8: Automobile | D8: Short term (up to 2 weeks) | E8: Buy | F8: Strong Buy | G8: 0.21183931 | H8: 0.11425674 | I8: 0.42819519 | J8: 0.0018773479 | K8: 5.7878251 | L8: 487.15 | M8: 17.653738 | N8: =ROUND(L8+'Read Me'!$D$30*M8,2) | O8: =ROUND(L8+'Read Me'!$C$30*M8,2) | P8: =ROUND(L8-'Read Me'!$B$30*M8,2) | Q8: =ABS(O8-L8)/L8 | R8: =ABS(L8-P8)/L8 | S8: 10 | T8: 6 | U8: Down | V8: Model rank: top 1% buy side / bottom 42% short side (buy bucket: Top 5%) | W8: ▼ Bear flag 21-Oct [works in reverse]; ▲ 2B bottom / Turtle soup 12-Oct [no edge] | X8: Not checked | Y8: AI model ranks it in the top 1% of stocks for a 2-week buy. Historically, top-5% names hit the target 21% of the time vs 15% for the average stock (weighted to falling markets like now), averaging +0.2% per trade after costs. Technicals: RSI 22; RS rating 13; -34% from 52-wk high; below 20-EMA.
A9: JBMA | B9: JBM Auto Ltd. | C9: Automobile | D9: Mid term (up to 3 months) | E9: Hold | F9: Hold / No fresh trade | G9: 0.29501647 | H9: 0.11434533 | I9: 0.49617973 | J9: 0.039061651 | K9: 2.0696017 | L9: 487.15 | M9: 17.653738 | U9: Down | V9: Model rank: top 8% buy side / top 49% short side (buy bucket: Top 15% (85-95%)) | W9: ▼ Bear flag 21-Oct [works in reverse]; ▲ 2B bottom / Turtle soup 12-Oct [no edge] | X9: Not checked | Y9: The model ranks it in the top 8% for a 3-month buy, but at this horizon its top ranks have not beaten the average stock in falling markets, so that is not counted; no proven signal active. Holders can keep; no fresh entry. Technicals: RSI 22; RS rating 13; -34% from 52-wk high; below a falling 50-DMA.
A10: JBMA | B10: JBM Auto Ltd. | C10: Automobile | D10: Long term (up to 1 year) | E10: Hold | F10: Hold / No fresh trade | G10: 0.3356492 | H10: 0.055927815 | I10: 0.49884743 | J10: 0.099800505 | K10: -3.9704276 | L10: 487.15 | M10: 17.653738 | U10: Down | V10: Model rank: top 20% buy side / bottom 27% short side (buy bucket: 70-85%); - RSI(14) rises back above 30 - fades (12-Oct): -1.6% vs avg stock, t 4.1 | W10: ▼ Bear flag 21-Oct [works in reverse]; ▲ 2B bottom / Turtle soup 12-Oct [no edge] | X10: Not checked | Y10: No edge either way for 1 year (buy-side model rank: 80th percentile; no proven signal active). Holders can keep; no fresh entry. Technicals: RSI 22; RS rating 13; -34% from 52-wk high; below a falling 200-DMA.
A11: RPOWER | B11: Reliance Power Ltd. | C11: Energy | D11: Short term (up to 2 weeks) | E11: Buy | F11: Strong Buy | G11: 0.21183931 | H11: 0.11425674 | I11: 0.42819519 | J11: 0.0018773479 | K11: 5.7878251 | L11: 16.43 | M11: 0.73021845 | N11: =ROUND(L11+'Read Me'!$D$30*M11,2) | O11: =ROUND(L11+'Read Me'!$C$30*M11,2) | P11: =ROUND(L11-'Read Me'!$B$30*M11,2) | Q11: =ABS(O11-L11)/L11 | R11: =ABS(L11-P11)/L11 | S11: 10 | T11: 6 | U11: Down | V11: Model rank: top 1% buy side / bottom 41% short side (buy bucket: Top 5%) | W11: ▼ Falling wedge - down breakout 19-Oct [no edge]; ▼ P&F bearish descending breakdown 15-Oct [works in reverse]; ▼ Wave-3 / ABC breakdown 15-Oct [no edge] | X11: Not checked | Y11: AI model ranks it in the top 1% of stocks for a 2-week buy. Historically, top-5% names hit the target 21% of the time vs 15% for the average stock (weighted to falling markets like now), averaging +0.2% per trade after costs. Technicals: RSI 17; RS rating 1; -66% from 52-wk high; below 20-EMA.
A12: RPOWER | B12: Reliance Power Ltd. | C12: Energy | D12: Mid term (up to 3 months) | E12: Hold | F12: Hold / No fresh trade | G12: 0.29501647 | H12: 0.11434533 | I12: 0.49617973 | J12: 0.039061651 | K12: 2.0696017 | L12: 16.43 | M12: 0.73021845 | U12: Down | V12: Model rank: top 8% buy side / top 50% short side (buy bucket: Top 15% (85-95%)) | W12: ▼ Falling wedge - down breakout 19-Oct [no edge]; ▼ P&F bearish descending breakdown 15-Oct [works in reverse]; ▼ Wave-3 / ABC breakdown 15-Oct [no edge] | X12: Not checked | Y12: The model ranks it in the top 8% for a 3-month buy, but at this horizon its top ranks have not beaten the average stock in falling markets, so that is not counted; no proven signal active. Holders can keep; no fresh entry. Technicals: RSI 17; RS rating 1; -66% from 52-wk high; below a falling 50-DMA.
A13: RPOWER | B13: Reliance Power Ltd. | C13: Energy | D13: Long term (up to 1 year) | E13: Hold | F13: Hold / No fresh trade | G13: 0.37136452 | H13: 0.037138628 | I13: 0.51670509 | J13: 0.11597254 | K13: -0.39889565 | L13: 16.43 | M13: 0.73021845 | U13: Down | V13: Model rank: top 22% buy side / bottom 3% short side (buy bucket: 70-85%) | W13: ▼ Falling wedge - down breakout 19-Oct [no edge]; ▼ P&F bearish descending breakdown 15-Oct [works in reverse]; ▼ Wave-3 / ABC breakdown 15-Oct [no edge] | X13: Not checked | Y13: No edge either way for 1 year (buy-side model rank: 78th percentile; no proven signal active). Holders can keep; no fresh entry. Technicals: RSI 17; RS rating 1; -66% from 52-wk high; below a falling 200-DMA.
A14: TRITURBINE | B14: Triveni Turbine Ltd. | C14: Industrial Manufacturing | D14: Short term (up to 2 weeks) | E14: Buy | F14: Strong Buy | G14: 0.21183931 | H14: 0.11425674 | I14: 0.42819519 | J14: 0.0018773479 | K14: 5.7878251 | L14: 445.05 | M14: 17.831958 | N14: =ROUND(L14+'Read Me'!$D$30*M14,2) | O14: =ROUND(L14+'Read Me'!$C$30*M14,2) | P14: =ROUND(L14-'Read Me'!$B$30*M14,2) | Q14: =ABS(O14-L14)/L14 | R14: =ABS(L14-P14)/L14 | S14: 10 | T14: 6 | U14: Down | V14: Model rank: top 1% buy side / bottom 32% short side (buy bucket: Top 5%) | W14: ▼ Falling wedge - down breakout 19-Oct [no edge]; ▲ 2B bottom / Turtle soup 15-Oct [no edge]; ▲ Wyckoff spring 15-Oct [works in reverse]; ▲ Bullish AB=CD 13-Oct [no edge] | X14: Mixed | Y14: AI model ranks it in the top 1% of stocks for a 2-week buy. Historically, top-5% names hit the target 21% of the time vs 15% for the average stock (weighted to falling markets like now), averaging +0.2% per trade after costs. Technicals: RSI 20; RS rating 19; -43% from 52-wk high; below 20-EMA. Results Q1 FY27 (Apr-Jun 2026) - revenue: +19.2% to Rs 443 Cr; profit: -21% to Rs 51 Cr (mixed).
A15: TRITURBINE | B15: Triveni Turbine Ltd. | C15: Industrial Manufacturing | D15: Mid term (up to 3 months) | E15: Hold | F15: Hold / No fresh trade | G15: 0.31745648 | H15: 0.07441852 | I15: 0.50235869 | J15: 0.043229003 | K15: 4.3136018 | L15: 445.05 | M15: 17.831958 | U15: Down | V15: Model rank: top 2% buy side / bottom 18% short side (buy bucket: Top 5%) | W15: ▼ Falling wedge - down breakout 19-Oct [no edge]; ▲ 2B bottom / Turtle soup 15-Oct [no edge]; ▲ Wyckoff spring 15-Oct [works in reverse]; ▲ Bullish AB=CD 13-Oct [no edge] | X15: Mixed | Y15: The model ranks it in the top 2% for a 3-month buy, but at this horizon its top ranks have not beaten the average stock in falling markets, so that is not counted; no proven signal active. Holders can keep; no fresh entry. Technicals: RSI 20; RS rating 19; -43% from 52-wk high; below a falling 50-DMA. Results Q1 FY27 (Apr-Jun 2026) - revenue: +19.2% to Rs 443 Cr; profit: -21% to Rs 51 Cr (mixed).
A16: TRITURBINE | B16: Triveni Turbine Ltd. | C16: Industrial Manufacturing | D16: Long term (up to 1 year) | E16: Hold | F16: Hold / No fresh trade | G16: 0.38248096 | H16: 0.055927815 | I16: 0.53353852 | J16: 0.1286861 | K16: 0.71274827 | L16: 445.05 | M16: 17.831958 | U16: Down | V16: Model rank: bottom 43% buy side / bottom 26% short side (buy bucket: 20-50%) | W16: ▼ Falling wedge - down breakout 19-Oct [no edge]; ▲ 2B bottom / Turtle soup 15-Oct [no edge]; ▲ Wyckoff spring 15-Oct [works in reverse]; ▲ Bullish AB=CD 13-Oct [no edge] | X16: Mixed | Y16: No edge either way for 1 year (buy-side model rank: 43rd percentile; no proven signal active). Holders can keep; no fresh entry. Technicals: RSI 20; RS rating 19; -43% from 52-wk high; below a falling 200-DMA. Results Q1 FY27 (Apr-Jun 2026) - revenue: +19.2% to Rs 443 Cr; profit: -21% to Rs 51 Cr (mixed).
A17: EIDPARRY | B17: E.I.D. Parry (India) Ltd. | C17: Fertilisers & Pesticides | D17: Short term (up to 2 weeks) | E17: Buy | F17: Strong Buy | G17: 0.21183931 | H17: 0.14315289 | I17: 0.42819519 | J17: 0.0018773479 | K17: 5.7878251 | L17: 627.5 | M17: 20.020187 | N17: =ROUND(L17+'Read Me'!$D$30*M17,2) | O17: =ROUND(L17+'Read Me'!$C$30*M17,2) | P17: =ROUND(L17-'Read Me'!$B$30*M17,2) | Q17: =ABS(O17-L17)/L17 | R17: =ABS(L17-P17)/L17 | S17: 10 | T17: 6 | U17: Down | V17: Model rank: top 1% buy side / top 25% short side (buy bucket: Top 5%) | W17: ▼ P&F bearish descending breakdown 21-Oct [works in reverse]; ▲ 2B bottom / Turtle soup 19-Oct [no edge]; ▲ Downtrend-line breakout 12-Oct [works in reverse] | X17: Not checked | Y17: AI model ranks it in the top 1% of stocks for a 2-week buy. Historically, top-5% names hit the target 21% of the time vs 15% for the average stock (weighted to falling markets like now), averaging +0.2% per trade after costs. Technicals: RSI 28; RS rating 7; -44% from 52-wk high; below 20-EMA.
A18: EIDPARRY | B18: E.I.D. Parry (India) Ltd. | C18: Fertilisers & Pesticides | D18: Mid term (up to 3 months) | E18: Hold | F18: Hold / No fresh trade | G18: 0.28474942 | H18: 0.099596779 | I18: 0.49058663 | J18: 0.03589876 | K18: 1.0428963 | L18: 627.5 | M18: 20.020187 | U18: Down | V18: Model rank: top 20% buy side / bottom 37% short side (buy bucket: 70-85%) | W18: ▼ P&F bearish descending breakdown 21-Oct [works in reverse]; ▲ 2B bottom / Turtle soup 19-Oct [no edge]; ▲ Downtrend-line breakout 12-Oct [works in reverse] | X18: Not checked | Y18: No edge either way for 3 months (buy-side model rank: 80th percentile; no proven signal active). Holders can keep; no fresh entry. Technicals: RSI 28; RS rating 7; -44% from 52-wk high; below a falling 50-DMA.
A19: EIDPARRY | B19: E.I.D. Parry (India) Ltd. | C19: Fertilisers & Pesticides | D19: Long term (up to 1 year) | E19: Hold | F19: Hold / No fresh trade | G19: 0.37136452 | H19: 0.055927815 | I19: 0.51670509 | J19: 0.11597254 | K19: -0.39889565 | L19: 627.5 | M19: 20.020187 | U19: Down | V19: Model rank: top 27% buy side / bottom 43% short side (buy bucket: 70-85%) | W19: ▼ P&F bearish descending breakdown 21-Oct [works in reverse]; ▲ 2B bottom / Turtle soup 19-Oct [no edge]; ▲ Downtrend-line breakout 12-Oct [works in reverse] | X19: Not checked | Y19: No edge either way for 1 year (buy-side model rank: 73rd percentile; no proven signal active). Holders can keep; no fresh entry. Technicals: RSI 28; RS rating 7; -44% from 52-wk high; below a falling 200-DMA.
A20: NBCC | B20: NBCC (India) Ltd. | C20: Construction | D20: Short term (up to 2 weeks) | E20: Buy | F20: Strong Buy | G20: 0.21183931 | H20: 0.14315289 | I20: 0.42819519 | J20: 0.0018773479 | K20: 5.7878251 | L20: 67.9 | M20: 2.0767964 | N20: =ROUND(L20+'Read Me'!$D$30*M20,2) | O20: =ROUND(L20+'Read Me'!$C$30*M20,2) | P20: =ROUND(L20-'Read Me'!$B$30*M20,2) | Q20: =ABS(O20-L20)/L20 | R20: =ABS(L20-P20)/L20 | S20: 10 | T20: 6 | U20: Down | V20: Model rank: top 1% buy side / top 26% short side (buy bucket: Top 5%) | X20: Not checked | Y20: AI model ranks it in the top 1% of stocks for a 2-week buy. Historically, top-5% names hit the target 21% of the time vs 15% for the average stock (weighted to falling markets like now), averaging +0.2% per trade after costs. Technicals: RSI 22; RS rating 3; -46% from 52-wk high; below 20-EMA.
A21: NBCC | B21: NBCC (India) Ltd. | C21: Construction | D21: Mid term (up to 3 months) | E21: Hold | F21: Hold / No fresh trade | G21: 0.28353408 | H21: 0.099596779 | I21: 0.50020496 | J21: 0.038018651 | K21: 0.9213626 | L21: 67.9 | M21: 2.0767964 | U21: Down | V21: Model rank: top 36% buy side / bottom 25% short side (buy bucket: 50-70%) | X21: Not checked | Y21: No edge either way for 3 months (buy-side model rank: 64th percentile; no proven signal active). Holders can keep; no fresh entry. Technicals: RSI 22; RS rating 3; -46% from 52-wk high; below a falling 50-DMA.
A22: NBCC | B22: NBCC (India) Ltd. | C22: Construction | D22: Long term (up to 1 year) | E22: Hold | F22: Hold / No fresh trade | G22: 0.34676564 | H22: 0.055927815 | I22: 0.51568086 | J22: 0.11251406 | K22: -2.8587837 | L22: 67.9 | M22: 2.0767964 | U22: Down | V22: Model rank: bottom 43% buy side / bottom 24% short side (buy bucket: 20-50%); - RSI(14) rises back above 30 - fades (12-Oct): -1.6% vs avg stock, t 4.1 | X22: Not checked | Y22: No edge either way for 1 year (buy-side model rank: 43rd percentile; no proven signal active). Holders can keep; no fresh entry. Technicals: RSI 22; RS rating 3; -46% from 52-wk high; below a falling 200-DMA.
A23: GODFRYPHLP | B23: Godfrey Phillips India Ltd. | C23: Consumer Goods | D23: Short term (up to 2 weeks) | E23: Buy | F23: Strong Buy | G23: 0.21183931 | H23: 0.11425674 | I23: 0.42819519 | J23: 0.0018773479 | K23: 5.7878251 | L23: 1669 | M23: 55.242683 | N23: =ROUND(L23+'Read Me'!$D$30*M23,2) | O23: =ROUND(L23+'Read Me'!$C$30*M23,2) | P23: =ROUND(L23-'Read Me'!$B$30*M23,2) | Q23: =ABS(O23-L23)/L23 | R23: =ABS(L23-P23)/L23 | S23: 10 | T23: 6 | U23: Down | V23: Model rank: top 2% buy side / bottom 35% short side (buy bucket: Top 5%) | W23: ▼ Falling wedge - down breakout 22-Oct [no edge]; ▼ Hidden bearish divergence (MFI) 21-Oct [no edge]; ▼ Wave-3 / ABC breakdown 21-Oct [no edge]; ▲ Downtrend-line breakout 16-Oct [works in reverse] | X23: Not checked | Y23: AI model ranks it in the top 2% of stocks for a 2-week buy. Historically, top-5% names hit the target 21% of the time vs 15% for the average stock (weighted to falling markets like now), averaging +0.2% per trade after costs. Technicals: RSI 29; RS rating 7; -52% from 52-wk high; below 20-EMA.
A24: GODFRYPHLP | B24: Godfrey Phillips India Ltd. | C24: Consumer Goods | D24: Mid term (up to 3 months) | E24: Hold | F24: Hold / No fresh trade | G24: 0.28353408 | H24: 0.11434533 | I24: 0.50020496 | J24: 0.038018651 | K24: 0.9213626 | L24: 1669 | M24: 55.242683 | U24: Down | V24: Model rank: top 37% buy side / top 40% short side (buy bucket: 50-70%) | W24: ▼ Falling wedge - down breakout 22-Oct [no edge]; ▼ Hidden bearish divergence (MFI) 21-Oct [no edge]; ▼ Wave-3 / ABC breakdown 21-Oct [no edge]; ▲ Downtrend-line breakout 16-Oct [works in reverse] | X24: Not checked | Y24: No edge either way for 3 months (buy-side model rank: 63rd percentile; no proven signal active). Holders can keep; no fresh entry. Technicals: RSI 29; RS rating 7; -52% from 52-wk high; below a falling 50-DMA.
A25: GODFRYPHLP | B25: Godfrey Phillips India Ltd. | C25: Consumer Goods | D25: Long term (up to 1 year) | E25: Hold | F25: Hold / No fresh trade | G25: 0.34676564 | H25: 0.071868264 | I25: 0.51568086 | J25: 0.11251406 | K25: -2.8587837 | L25: 1669 | M25: 55.242683 | U25: Down | V25: Model rank: bottom 26% buy side / top 32% short side (buy bucket: 20-50%); - RSI(14) rises back above 30 - fades (09-Oct): -1.6% vs avg stock, t 4.1 | W25: ▼ Falling wedge - down breakout 22-Oct [no edge]; ▼ Hidden bearish divergence (MFI) 21-Oct [no edge]; ▼ Wave-3 / ABC breakdown 21-Oct [no edge]; ▲ Downtrend-line breakout 16-Oct [works in reverse] | X25: Not checked | Y25: No edge either way for 1 year (buy-side model rank: 26th percentile; no proven signal active). Holders can keep; no fresh entry. Technicals: RSI 29; RS rating 7; -52% from 52-wk high; below a falling 200-DMA.
A26: GMDCLTD | B26: Gujarat Mineral Development Corporation Ltd. | C26: Metals | D26: Short term (up to 2 weeks) | E26: Buy | F26: Strong Buy | G26: 0.21183931 | H26: 0.13461342 | I26: 0.42819519 | J26: 0.0018773479 | K26: 5.7878251 | L26: 424.6 | M26: 15.382904 | N26: =ROUND(L26+'Read Me'!$D$30*M26,2) | O26: =ROUND(L26+'Read Me'!$C$30*M26,2) | P26: =ROUND(L26-'Read Me'!$B$30*M26,2) | Q26: =ABS(O26-L26)/L26 | R26: =ABS(L26-P26)/L26 | S26: 10 | T26: 6 | U26: Down | V26: Model rank: top 2% buy side / top 47% short side (buy bucket: Top 5%) | W26: ▼ Bear flag 21-Oct [works in reverse]; ▲ 2B bottom / Turtle soup 19-Oct [no edge] | X26: Not checked | Y26: AI model ranks it in the top 2% of stocks for a 2-week buy. Historically, top-5% names hit the target 21% of the time vs 15% for the average stock (weighted to falling markets like now), averaging +0.2% per trade after costs. Technicals: RSI 21; RS rating 6; -45% from 52-wk high; below 20-EMA.
A27: GMDCLTD | B27: Gujarat Mineral Development Corporation Ltd. | C27: Metals | D27: Mid term (up to 3 months) | E27: Hold | F27: Hold / No fresh trade | G27: 0.28353408 | H27: 0.099596779 | I27: 0.50020496 | J27: 0.038018651 | K27: 0.9213626 | L27: 424.6 | M27: 15.382904 | U27: Down | V27: Model rank: top 32% buy side / bottom 42% short side (buy bucket: 50-70%) | W27: ▼ Bear flag 21-Oct [works in reverse]; ▲ 2B bottom / Turtle soup 19-Oct [no edge] | X27: Not checked | Y27: No edge either way for 3 months (buy-side model rank: 68th percentile; no proven signal active). Holders can keep; no fresh entry. Technicals: RSI 21; RS rating 6; -45% from 52-wk high; below a falling 50-DMA.
A28: GMDCLTD | B28: Gujarat Mineral Development Corporation Ltd. | C28: Metals | D28: Long term (up to 1 year) | E28: Hold | F28: Hold / No fresh trade | G28: 0.35529798 | H28: 0.055927815 | I28: 0.51111196 | J28: 0.10959171 | K28: -2.00555 | L28: 424.6 | M28: 15.382904 | U28: Down | V28: Model rank: top 38% buy side / bottom 22% short side (buy bucket: 50-70%); - RSI(14) rises back above 30 - fades (16-Oct): -1.6% vs avg stock, t 4.1 | W28: ▼ Bear flag 21-Oct [works in reverse]; ▲ 2B bottom / Turtle soup 19-Oct [no edge] | X28: Not checked | Y28: No edge either way for 1 year (buy-side model rank: 62nd percentile; no proven signal active). Holders can keep; no fresh entry. Technicals: RSI 21; RS rating 6; -45% from 52-wk high; below a falling 200-DMA.
A29: OLECTRA | B29: Olectra Greentech Ltd. | C29: Automobile | D29: Short term (up to 2 weeks) | E29: Buy | F29: Strong Buy | G29: 0.21183931 | H29: 0.11425674 | I29: 0.42819519 | J29: 0.0018773479 | K29: 5.7878251 | L29: 955.7 | M29: 36.002199 | N29: =ROUND(L29+'Read Me'!$D$30*M29,2) | O29: =ROUND(L29+'Read Me'!$C$30*M29,2) | P29: =ROUND(L29-'Read Me'!$B$30*M29,2) | Q29: =ABS(O29-L29)/L29 | R29: =ABS(L29-P29)/L29 | S29: 10 | T29: 6 | U29: Down | V29: Model rank: top 2% buy side / bottom 30% short side (buy bucket: Top 5%) | W29: ▼ Bear pennant 21-Oct [no edge] | X29: Not checked | Y29: AI model ranks it in the top 2% of stocks for a 2-week buy. Historically, top-5% names hit the target 21% of the time vs 15% for the average stock (weighted to falling markets like now), averaging +0.2% per trade after costs. Technicals: RSI 23; RS rating 9; -39% from 52-wk high; below 20-EMA.
A30: OLECTRA | B30: Olectra Greentech Ltd. | C30: Automobile | D30: Mid term (up to 3 months) | E30: Hold | F30: Hold / No fresh trade | G30: 0.31745648 | H30: 0.099596779 | I30: 0.50235869 | J30: 0.043229003 | K30: 4.3136018 | L30: 955.7 | M30: 36.002199 | U30: Down | V30: Model rank: top 1% buy side / bottom 26% short side (buy bucket: Top 5%) | W30: ▼ Bear pennant 21-Oct [no edge] | X30: Not checked | Y30: The model ranks it in the top 1% for a 3-month buy, but at this horizon its top ranks have not beaten the average stock in falling markets, so that is not counted; no proven signal active. Holders can keep; no fresh entry. Technicals: RSI 23; RS rating 9; -39% from 52-wk high; below a falling 50-DMA.
A31: OLECTRA | B31: Olectra Greentech Ltd. | C31: Automobile | D31: Long term (up to 1 year) | E31: Hold | F31: Hold / No fresh trade | G31: 0.35529798 | H31: 0.055927815 | I31: 0.51111196 | J31: 0.10959171 | K31: -2.00555 | L31: 955.7 | M31: 36.002199 | U31: Down | V31: Model rank: top 35% buy side / bottom 27% short side (buy bucket: 50-70%); - RSI(14) rises back above 30 - fades (13-Oct): -1.6% vs avg stock, t 4.1 | W31: ▼ Bear pennant 21-Oct [no edge] | X31: Not checked | Y31: No edge either way for 1 year (buy-side model rank: 65th percentile; no proven signal active). Holders can keep; no fresh entry. Technicals: RSI 23; RS rating 9; -39% from 52-wk high; below a falling 200-DMA.
A32: THERMAX | B32: Thermax Ltd. | C32: Industrial Manufacturing | D32: Short term (up to 2 weeks) | E32: Buy | F32: Strong Buy | G32: 0.21183931 | H32: 0.11425674 | I32: 0.42819519 | J32: 0.0018773479 | K32: 5.7878251 | L32: 3096 | M32: 112.3196 | N32: =ROUND(L32+'Read Me'!$D$30*M32,2) | O32: =ROUND(L32+'Read Me'!$C$30*M32,2) | P32: =ROUND(L32-'Read Me'!$B$30*M32,2) | Q32: =ABS(O32-L32)/L32 | R32: =ABS(L32-P32)/L32 | S32: 10 | T32: 6 | U32: Down | V32: Model rank: top 2% buy side / bottom 43% short side (buy bucket: Top 5%) | W32: ▼ P&F bearish descending breakdown 23-Oct [works in reverse]; ▲ 2B bottom / Turtle soup 21-Oct [no edge]; ▼ Hidden bearish divergence (MACD hist) 21-Oct [no edge]; ▼ Hidden bearish divergence (MFI) 21-Oct [no edge] | X32: Negative | Y32: AI model ranks it in the top 2% of stocks for a 2-week buy. Historically, top-5% names hit the target 21% of the time vs 15% for the average stock (weighted to falling markets like now), averaging +0.2% per trade after costs. Technicals: RSI 31; RS rating 28; -41% from 52-wk high; below 20-EMA. Results Q1 FY27 (Apr-Jun 2026) - revenue: +7% to Rs 2,303 Cr; profit: -83% to about Rs 25 Cr (negative).
A33: THERMAX | B33: Thermax Ltd. | C33: Industrial Manufacturing | D33: Mid term (up to 3 months) | E33: Hold | F33: Hold / No fresh trade | G33: 0.31745648 | H33: 0.099596779 | I33: 0.50235869 | J33: 0.043229003 | K33: 4.3136018 | L33: 3096 | M33: 112.3196 | U33: Down | V33: Model rank: top 4% buy side / bottom 27% short side (buy bucket: Top 5%) | W33: ▼ P&F bearish descending breakdown 23-Oct [works in reverse]; ▲ 2B bottom / Turtle soup 21-Oct [no edge]; ▼ Hidden bearish divergence (MACD hist) 21-Oct [no edge]; ▼ Hidden bearish divergence (MFI) 21-Oct [no edge] | X33: Negative | Y33: The model ranks it in the top 4% for a 3-month buy, but at this horizon its top ranks have not beaten the average stock in falling markets, so that is not counted; no proven signal active. Holders can keep; no fresh entry. Technicals: RSI 31; RS rating 28; -41% from 52-wk high; below a falling 50-DMA. Results Q1 FY27 (Apr-Jun 2026) - revenue: +7% to Rs 2,303 Cr; profit: -83% to about Rs 25 Cr (negative).
A34: THERMAX | B34: Thermax Ltd. | C34: Industrial Manufacturing | D34: Long term (up to 1 year) | E34: Hold | F34: Hold / No fresh trade | G34: 0.34676564 | H34: 0.055927815 | I34: 0.51568086 | J34: 0.11251406 | K34: -2.8587837 | L34: 3096 | M34: 112.3196 | U34: Sideways | V34: Model rank: bottom 38% buy side / bottom 48% short side (buy bucket: 20-50%); - RSI(14) rises back above 30 - fades (09-Oct): -1.6% vs avg stock, t 4.1 | W34: ▼ P&F bearish descending breakdown 23-Oct [works in reverse]; ▲ 2B bottom / Turtle soup 21-Oct [no edge]; ▼ Hidden bearish divergence (MACD hist) 21-Oct [no edge]; ▼ Hidden bearish divergence (MFI) 21-Oct [no edge] | X34: Negative | Y34: No edge either way for 1 year (buy-side model rank: 38th percentile; no proven signal active). Holders can keep; no fresh entry. Technicals: RSI 31; RS rating 28; -41% from 52-wk high; below a rising 200-DMA. Results Q1 FY27 (Apr-Jun 2026) - revenue: +7% to Rs 2,303 Cr; profit: -83% to about Rs 25 Cr (negative).
A35: VOLTAS | B35: Voltas Ltd. | C35: Consumer Goods | D35: Short term (up to 2 weeks) | E35: Buy | F35: Strong Buy | G35: 0.21183931 | H35: 0.13461342 | I35: 0.42819519 | J35: 0.0018773479 | K35: 5.7878251 | L35: 950 | M35: 31.002142 | N35: =ROUND(L35+'Read Me'!$D$30*M35,2) | O35: =ROUND(L35+'Read Me'!$C$30*M35,2) | P35: =ROUND(L35-'Read Me'!$B$30*M35,2) | Q35: =ABS(O35-L35)/L35 | R35: =ABS(L35-P35)/L35 | S35: 10 | T35: 6 | U35: Down | V35: Model rank: top 3% buy side / top 43% short side (buy bucket: Top 5%) | W35: ▼ Bear flag 21-Oct [works in reverse] | X35: Not checked | Y35: AI model ranks it in the top 3% of stocks for a 2-week buy. Historically, top-5% names hit the target 21% of the time vs 15% for the average stock (weighted to falling markets like now), averaging +0.2% per trade after costs. Technicals: RSI 24; RS rating 3; -40% from 52-wk high; below 20-EMA.
A36: VOLTAS | B36: Voltas Ltd. | C36: Consumer Goods | D36: Mid term (up to 3 months) | E36: Hold | F36: Hold / No fresh trade | G36: 0.28353408 | H36: 0.099596779 | I36: 0.50020496 | J36: 0.038018651 | K36: 0.9213626 | L36: 950 | M36: 31.002142 | U36: Down | V36: Model rank: top 46% buy side / bottom 25% short side (buy bucket: 50-70%) | W36: ▼ Bear flag 21-Oct [works in reverse] | X36: Not checked | Y36: No edge either way for 3 months (buy-side model rank: 54th percentile; no proven signal active). Holders can keep; no fresh entry. Technicals: RSI 24; RS rating 3; -40% from 52-wk high; below a falling 50-DMA.
A37: VOLTAS | B37: Voltas Ltd. | C37: Consumer Goods | D37: Long term (up to 1 year) | E37: Hold | F37: Hold / No fresh trade | G37: 0.32912876 | H37: 0.071868264 | I37: 0.51140418 | J37: 0.11040694 | K37: -4.6224715 | L37: 950 | M37: 31.002142 | U37: Down | V37: Model rank: bottom 6% buy side / top 48% short side (buy bucket: Bottom 20%); - RSI(14) rises back above 30 - fades (13-Oct): -1.6% vs avg stock, t 4.1 | W37: ▼ Bear flag 21-Oct [works in reverse] | X37: Not checked | Y37: No edge either way for 1 year (buy-side model rank: 6th percentile; no proven signal active). Holders can keep; no fresh entry. Technicals: RSI 24; RS rating 3; -40% from 52-wk high; below a falling 200-DMA.
A38: AVANTIFEED | B38: Avanti Feeds Ltd. | C38: Fast Moving Consumer Goods | D38: Short term (up to 2 weeks) | E38: Buy | F38: Strong Buy | G38: 0.21183931 | H38: 0.14315289 | I38: 0.42819519 | J38: 0.0018773479 | K38: 5.7878251 | L38: 675.7 | M38: 23.153853 | N38: =ROUND(L38+'Read Me'!$D$30*M38,2) | O38: =ROUND(L38+'Read Me'!$C$30*M38,2) | P38: =ROUND(L38-'Read Me'!$B$30*M38,2) | Q38: =ABS(O38-L38)/L38 | R38: =ABS(L38-P38)/L38 | S38: 10 | T38: 6 | U38: Down | V38: Model rank: top 3% buy side / top 16% short side (buy bucket: Top 5%) | W38: ▲ Downtrend-line breakout 14-Oct [works in reverse]; ▲ Falling wedge - up breakout 14-Oct [no edge]; ▲ 2B bottom / Turtle soup 12-Oct [no edge] | X38: Not checked | Y38: AI model ranks it in the top 3% of stocks for a 2-week buy. Historically, top-5% names hit the target 21% of the time vs 15% for the average stock (weighted to falling markets like now), averaging +0.2% per trade after costs. Technicals: RSI 28; RS rating 9; -58% from 52-wk high; below 20-EMA; delivery % falling (-6 pts vs 20-day).
A39: AVANTIFEED | B39: Avanti Feeds Ltd. | C39: Fast Moving Consumer Goods | D39: Mid term (up to 3 months) | E39: Hold | F39: Hold / No fresh trade | G39: 0.31745648 | H39: 0.099596779 | I39: 0.50235869 | J39: 0.043229003 | K39: 4.3136018 | L39: 675.7 | M39: 23.153853 | U39: Down | V39: Model rank: top 3% buy side / bottom 48% short side (buy bucket: Top 5%) | W39: ▲ Downtrend-line breakout 14-Oct [works in reverse]; ▲ Falling wedge - up breakout 14-Oct [no edge]; ▲ 2B bottom / Turtle soup 12-Oct [no edge] | X39: Not checked | Y39: The model ranks it in the top 3% for a 3-month buy, but at this horizon its top ranks have not beaten the average stock in falling markets, so that is not counted; no proven signal active. Holders can keep; no fresh entry. Technicals: RSI 28; RS rating 9; -58% from 52-wk high; below a falling 50-DMA; delivery % falling (-6 pts vs 20-day).
A40: AVANTIFEED | B40: Avanti Feeds Ltd. | C40: Fast Moving Consumer Goods | D40: Long term (up to 1 year) | E40: Hold | F40: Hold / No fresh trade | G40: 0.35529798 | H40: 0.071868264 | I40: 0.51111196 | J40: 0.10959171 | K40: -2.00555 | L40: 675.7 | M40: 23.153853 | U40: Down | V40: Model rank: top 46% buy side / top 36% short side (buy bucket: 50-70%); - RSI(14) rises back above 30 - fades (12-Oct): -1.6% vs avg stock, t 4.1 | W40: ▲ Downtrend-line breakout 14-Oct [works in reverse]; ▲ Falling wedge - up breakout 14-Oct [no edge]; ▲ 2B bottom / Turtle soup 12-Oct [no edge] | X40: Not checked | Y40: No edge either way for 1 year (buy-side model rank: 54th percentile; no proven signal active). Holders can keep; no fresh entry. Technicals: RSI 28; RS rating 9; -58% from 52-wk high; below a falling 200-DMA; delivery % falling (-6 pts vs 20-day).
...

Sheet By Stock
A1: Symbol | B1: Company | C1: Sector | D1: Current price Rs | E1: Short-term call | F1: Short-term buy confidence | G1: Mid-term call | H1: Mid-term buy confidence | I1: Long-term call | J1: Long-term buy confidence | K1: Short-term trend | L1: Mid-term trend | M1: Long-term trend | N1: RS rating (1-99) | O1: % from 52-wk high | P1: Active chart patterns (last 10 sessions) | Q1: Results / news check
A2: KOTAKBANK | B2: Kotak Mahindra Bank Ltd. | C2: Financial Services | D2: 430.5 | E2: Buy | F2: 0.17817111 | G2: Buy | H2: 0.31279249 | I2: Accumulate (buy on dips) | J2: 0.39511908 | K2: Sideways | L2: Up | M2: Sideways | N2: 82 | O2: -0.050088263 | P2: ▼ 2B top / Turtle soup 19-Oct [weak edge]; ▼ Bearish AB=CD 19-Oct [no edge]; ▼ Wyckoff upthrust 16-Oct [works] | Q2: Supportive: Steady earnings growth.
A3: JWL | B3: Jupiter Wagons Ltd. | C3: Industrial Manufacturing | D3: 173.39 | E3: Strong Buy | F3: 0.21183931 | G3: Hold / No fresh trade | H3: 0.29501647 | I3: Hold / No fresh trade | J3: 0.35529798 | K3: Down | L3: Down | M3: Down | N3: 1 | O3: -0.51600838 | P3: ▼ Descending broadening wedge - down breakout 14-Oct [no edge]; ▼ Falling wedge - down breakout 09-Oct [no edge] | Q3: Not checked
A4: JBMA | B4: JBM Auto Ltd. | C4: Automobile | D4: 487.15 | E4: Strong Buy | F4: 0.21183931 | G4: Hold / No fresh trade | H4: 0.29501647 | I4: Hold / No fresh trade | J4: 0.3356492 | K4: Down | L4: Down | M4: Down | N4: 13 | O4: -0.34035206 | P4: ▼ Bear flag 21-Oct [works in reverse]; ▲ 2B bottom / Turtle soup 12-Oct [no edge] | Q4: Not checked
A5: RPOWER | B5: Reliance Power Ltd. | C5: Energy | D5: 16.43 | E5: Strong Buy | F5: 0.21183931 | G5: Hold / No fresh trade | H5: 0.29501647 | I5: Hold / No fresh trade | J5: 0.37136452 | K5: Down | L5: Down | M5: Down | N5: 1 | O5: -0.65591621 | P5: ▼ Falling wedge - down breakout 19-Oct [no edge]; ▼ P&F bearish descending breakdown 15-Oct [works in reverse]; ▼ Wave-3 / ABC breakdown 15-Oct [no edge] | Q5: Not checked
A6: TRITURBINE | B6: Triveni Turbine Ltd. | C6: Industrial Manufacturing | D6: 445.05 | E6: Strong Buy | F6: 0.21183931 | G6: Hold / No fresh trade | H6: 0.31745648 | I6: Hold / No fresh trade | J6: 0.38248096 | K6: Down | L6: Down | M6: Down | N6: 19 | O6: -0.43492889 | P6: ▼ Falling wedge - down breakout 19-Oct [no edge]; ▲ 2B bottom / Turtle soup 15-Oct [no edge]; ▲ Wyckoff spring 15-Oct [works in reverse] | Q6: Mixed: Margins compressed; export and aftermarket orders strong.
A7: EIDPARRY | B7: E.I.D. Parry (India) Ltd. | C7: Fertilisers & Pesticides | D7: 627.5 | E7: Strong Buy | F7: 0.21183931 | G7: Hold / No fresh trade | H7: 0.28474942 | I7: Hold / No fresh trade | J7: 0.37136452 | K7: Down | L7: Down | M7: Down | N7: 7 | O7: -0.43872986 | P7: ▼ P&F bearish descending breakdown 21-Oct [works in reverse]; ▲ 2B bottom / Turtle soup 19-Oct [no edge]; ▲ Downtrend-line breakout 12-Oct [works in reverse] | Q7: Not checked
A8: NBCC | B8: NBCC (India) Ltd. | C8: Construction | D8: 67.9 | E8: Strong Buy | F8: 0.21183931 | G8: Hold / No fresh trade | H8: 0.28353408 | I8: Hold / No fresh trade | J8: 0.34676564 | K8: Down | L8: Down | M8: Down | N8: 3 | O8: -0.46046883 | Q8: Not checked
A9: GODFRYPHLP | B9: Godfrey Phillips India Ltd. | C9: Consumer Goods | D9: 1669 | E9: Strong Buy | F9: 0.21183931 | G9: Hold / No fresh trade | H9: 0.28353408 | I9: Hold / No fresh trade | J9: 0.34676564 | K9: Down | L9: Down | M9: Down | N9: 7 | O9: -0.51649815 | P9: ▼ Falling wedge - down breakout 22-Oct [no edge]; ▼ Hidden bearish divergence (MFI) 21-Oct [no edge]; ▼ Wave-3 / ABC breakdown 21-Oct [no edge] | Q9: Not checked
A10: GMDCLTD | B10: Gujarat Mineral Development Corporation Ltd. | C10: Metals | D10: 424.6 | E10: Strong Buy | F10: 0.21183931 | G10: Hold / No fresh trade | H10: 0.28353408 | I10: Hold / No fresh trade | J10: 0.35529798 | K10: Down | L10: Down | M10: Down | N10: 6 | O10: -0.44992874 | P10: ▼ Bear flag 21-Oct [works in reverse]; ▲ 2B bottom / Turtle soup 19-Oct [no edge] | Q10: Not checked
A11: OLECTRA | B11: Olectra Greentech Ltd. | C11: Automobile | D11: 955.7 | E11: Strong Buy | F11: 0.21183931 | G11: Hold / No fresh trade | H11: 0.31745648 | I11: Hold / No fresh trade | J11: 0.35529798 | K11: Down | L11: Down | M11: Down | N11: 9 | O11: -0.39274368 | P11: ▼ Bear pennant 21-Oct [no edge] | Q11: Not checked
A12: THERMAX | B12: Thermax Ltd. | C12: Industrial Manufacturing | D12: 3096 | E12: Strong Buy | F12: 0.21183931 | G12: Hold / No fresh trade | H12: 0.31745648 | I12: Hold / No fresh trade | J12: 0.34676564 | K12: Down | L12: Down | M12: Sideways | N12: 28 | O12: -0.41339195 | P12: ▼ P&F bearish descending breakdown 23-Oct [works in reverse]; ▲ 2B bottom / Turtle soup 21-Oct [no edge]; ▼ Hidden bearish divergence (MACD hist) 21-Oct [no edge] | Q12: Negative: Rs 91 Cr one-off project cost overrun; order book Rs 14,045 Cr.
A13: VOLTAS | B13: Voltas Ltd. | C13: Consumer Goods | D13: 950 | E13: Strong Buy | F13: 0.21183931 | G13: Hold / No fresh trade | H13: 0.28353408 | I13: Hold / No fresh trade | J13: 0.32912876 | K13: Down | L13: Down | M13: Down | N13: 3 | O13: -0.39968403 | P13: ▼ Bear flag 21-Oct [works in reverse] | Q13: Not checked
A14: AVANTIFEED | B14: Avanti Feeds Ltd. | C14: Fast Moving Consumer Goods | D14: 675.7 | E14: Strong Buy | F14: 0.21183931 | G14: Hold / No fresh trade | H14: 0.31745648 | I14: Hold / No fresh trade | J14: 0.35529798 | K14: Down | L14: Down | M14: Down | N14: 9 | O14: -0.57604465 | P14: ▲ Downtrend-line breakout 14-Oct [works in reverse]; ▲ Falling wedge - up breakout 14-Oct [no edge]; ▲ 2B bottom / Turtle soup 12-Oct [no edge] | Q14: Not checked
A15: ATGL | B15: Adani Total Gas Ltd. | C15: Energy | D15: 529.5 | E15: Strong Buy | F15: 0.21183931 | G15: Hold / No fresh trade | H15: 0.28353408 | I15: Hold / No fresh trade | J15: 0.3910133 | K15: Down | L15: Down | M15: Down | N15: 34 | O15: -0.38419491 | P15: ▲ Bullish AB=CD 14-Oct [no edge]; ▲ Bullish Wolfe wave 14-Oct [no edge] | Q15: Not checked
A16: CESC | B16: CESC Ltd. | C16: Energy | D16: 124.79 | E16: Strong Buy | F16: 0.21183931 | G16: Hold / No fresh trade | H16: 0.28353408 | I16: Hold / No fresh trade | J16: 0.35529798 | K16: Down | L16: Down | M16: Down | N16: 9 | O16: -0.38977997 | P16: ▼ P&F bearish descending breakdown 23-Oct [works in reverse]; ▲ 2B bottom / Turtle soup 09-Oct [no edge]; ▲ Downtrend-line breakout 09-Oct [works in reverse] | Q16: Not checked
A17: KEC | B17: Kec International Ltd. | C17: Construction | D17: 327.75 | E17: Strong Buy | F17: 0.21183931 | G17: Hold / No fresh trade | H17: 0.31745648 | I17: Hold / No fresh trade | J17: 0.34676564 | K17: Down | L17: Down | M17: Down | N17: 1 | O17: -0.62258175 | P17: ▼ P&F bearish descending breakdown 19-Oct [works in reverse]; ▼ Wave-3 / ABC breakdown 19-Oct [no edge]; ▼ Hidden bearish divergence (MFI) 12-Oct [no edge] | Q17: Not checked
A18: TITAGARH | B18: Titagarh Rail Systems Ltd. | C18: Industrial Manufacturing | D18: 663.35 | E18: Strong Buy | F18: 0.21183931 | G18: Hold / No fresh trade | H18: 0.31745648 | I18: Hold / No fresh trade | J18: 0.37136452 | K18: Down | L18: Down | M18: Down | N18: 25 | O18: -0.3168383 | P18: ▲ Wyckoff spring 13-Oct [works in reverse] | Q18: Not checked
A19: RVNL | B19: Rail Vikas Nigam Ltd. | C19: Construction | D19: 181.31 | E19: Strong Buy | F19: 0.21183931 | G19: Hold / No fresh trade | H19: 0.29501647 | I19: Hold / No fresh trade | J19: 0.3910133 | K19: Down | L19: Down | M19: Down | N19: 2 | O19: -0.54751686 | P19: ▼ Wave-3 / ABC breakdown 23-Oct [no edge]; ▼ P&F bearish descending breakdown 22-Oct [works in reverse]; ▲ 2B bottom / Turtle soup 21-Oct [no edge] | Q19: Not checked
A20: AIAENG | B20: AIA Engineering Ltd. | C20: Industrial Manufacturing | D20: 3579.2 | E20: Strong Buy | F20: 0.21183931 | G20: Hold / No fresh trade | H20: 0.28474942 | I20: Hold / No fresh trade | J20: 0.35529798 | K20: Down | L20: Down | M20: Down | N20: 47 | O20: -0.30903475 | P20: ▲ 2B bottom / Turtle soup 15-Oct [no edge]; ▼ Horizontal support breakdown (3+ touches) 15-Oct [weak edge]; ▲ Bullish Wolfe wave 12-Oct [no edge] | Q20: Not checked
... A44: DIXON | B44: Dixon Technologies (India) Ltd. | C44: Consumer Goods | D44: 11191 | E44: Hold / No fresh trade | F44: 0.17962269 | G44: Hold / No fresh trade | H44: 0.27614069 | I44: Hold / No fresh trade | J44: 0.37795048 | K44: Down | L44: Down | M44: Down | N44: 38 | O44: -0.34166718 | P44: ▼ Uptrend-line breakdown 19-Oct [no edge]; ▲ Wyckoff spring 13-Oct [works in reverse]; ▲ 2B bottom / Turtle soup 09-Oct [no edge] | Q44: Not checked
A45: EXIDEIND | B45: Exide Industries Ltd. | C45: Automobile | D45: 331.95 | E45: Hold / No fresh trade | F45: 0.17962269 | G45: Hold / No fresh trade | H45: 0.28474942 | I45: Hold / No fresh trade | J45: 0.38447092 | K45: Down | L45: Down | M45: Sideways | N45: 34 | O45: -0.33128525 | Q45: Not checked
A46: SCHNEIDER | B46: Schneider Electric Infrastructure Ltd. | C46: Industrial Manufacturing | D46: 1114.1 | E46: Hold / No fresh trade | F46: 0.17962269 | G46: Hold / No fresh trade | H46: 0.28219231 | I46: Hold / No fresh trade | J46: 0.39558736 | K46: Down | L46: Down | M46: Up | N46: 86 | O46: -0.28029716 | P46: ▲ Key reversal day (bullish) 22-Oct [no edge]; ▲ Wyckoff spring 22-Oct [works in reverse]; ▼ Horizontal support breakdown (3+ touches) 19-Oct [weak edge] | Q46: Mixed: Record order inflow but margin pressure.
A47: AMBER | B47: Amber Enterprises India Ltd. | C47: Consumer Goods | D47: 6004.5 | E47: Hold / No fresh trade | F47: 0.17962269 | G47: Hold / No fresh trade | H47: 0.27001717 | I47: Hold / No fresh trade | J47: 0.36484408 | K47: Down | L47: Down | M47: Down | N47: 25 | O47: -0.33090038 | P47: ▼ Channel down - down breakout 23-Oct [no edge]; ▼ Hidden bearish divergence (MACD hist) 21-Oct [no edge]; ▼ Hidden bearish divergence (MFI) 21-Oct [no edge] | Q47: Not checked
A48: ZEEL | B48: Zee Entertainment Enterprises Ltd. | C48: Media & Entertainment | D48: 65.42 | E48: Hold / No fresh trade | F48: 0.17962269 | G48: Hold / No fresh trade | H48: 0.28353408 | I48: Hold / No fresh trade | J48: 0.32912876 | K48: Down | L48: Down | M48: Down | N48: 2 | O48: -0.44723278 | P48: ▼ 52-week low breakdown 23-Oct [no edge]; ▼ P&F bearish descending breakdown 23-Oct [works in reverse]; ▼ Hidden bearish divergence (MACD hist) 22-Oct [no edge] | Q48: Not checked
A49: SUMICHEM | B49: Sumitomo Chemical India Ltd. | C49: Fertilisers & Pesticides | D49: 360.6 | E49: Hold / No fresh trade | F49: 0.17962269 | G49: Hold / No fresh trade | H49: 0.27001717 | I49: Hold / No fresh trade | J49: 0.3910133 | K49: Down | L49: Down | M49: Down | N49: 7 | O49: -0.36963551 | P49: ▼ 52-week low breakdown 23-Oct [no edge]; ▼ Bear flag 14-Oct [works in reverse]; ▼ Horizontal support breakdown (3+ touches) 14-Oct [weak edge] | Q49: Not checked
A50: KALYANKJIL | B50: Kalyan Jewellers India Ltd. | C50: Consumer Goods | D50: 512 | E50: Hold / No fresh trade | F50: 0.19087561 | G50: Hold / No fresh trade | H50: 0.27614069 | I50: Hold / No fresh trade | J50: 0.37795048 | K50: Down | L50: Down | M50: Up | N50: 73 | O50: -0.21103321 | P50: ▼ P&F bearish descending breakdown 23-Oct [works in reverse]; ▼ Dow trend reversal down 22-Oct [no edge]; ▼ Hidden bearish divergence (MACD hist) 22-Oct [no edge] | Q50: Not checked
A51: GODREJPROP | B51: Godrej Properties Ltd. | C51: Construction | D51: 1496.5 | E51: Hold / No fresh trade | F51: 0.17962269 | G51: Hold / No fresh trade | H51: 0.28353408 | I51: Hold / No fresh trade | J51: 0.34676564 | K51: Down | L51: Down | M51: Down | N51: 11 | O51: -0.36373299 | P51: ▼ Hidden bearish divergence (MACD hist) 21-Oct [no edge]; ▲ Bullish divergence (MACD hist) 15-Oct [no edge]; ▲ Bullish Quasimodo 13-Oct [tends to fail] | Q51: Not checked
A52: DLF | B52: DLF Ltd. | C52: Construction | D52: 657 | E52: Hold / No fresh trade | F52: 0.1843059 | G52: Hold / No fresh trade | H52: 0.27614069 | I52: Hold / No fresh trade | J52: 0.39558736 | K52: Sideways | L52: Sideways | M52: Sideways | N52: 70 | O52: -0.16465353 | P52: ▼ Bearish divergence (MACD hist) 21-Oct [tends to fail]; ▼ Bearish divergence (OBV) 21-Oct [no edge]; ▼ Bearish divergence (RSI) 21-Oct [works in reverse] | Q52: Not checked
A53: BHARATFORG | B53: Bharat Forge Ltd. | C53: Industrial Manufacturing | D53: 1711.2 | E53: Hold / No fresh trade | F53: 0.17962269 | G53: Hold / No fresh trade | H53: 0.27728413 | I53: Hold / No fresh trade | J53: 0.3910133 | K53: Down | L53: Down | M53: Sideways | N53: 71 | O53: -0.25437908 | P53: ▼ Wave-3 / ABC breakdown 22-Oct [no edge]; ▲ 2B bottom / Turtle soup 21-Oct [no edge]; ▲ Wyckoff spring 21-Oct [works in reverse] | Q53: Not checked
A54: GPIL | B54: Godawari Power and Ispat Ltd. | C54: Metals | D54: 192.34 | E54: Hold / No fresh trade | F54: 0.17962269 | G54: Hold / No fresh trade | H54: 0.28353408 | I54: Hold / No fresh trade | J54: 0.35529798 | K54: Down | L54: Down | M54: Down | N54: 10 | O54: -0.39893749 | P54: ▼ Bear flag 21-Oct [works in reverse] | Q54: Not checked
A55: DATAPATTNS | B55: Data Patterns (India) Ltd. | C55: Industrial Manufacturing | D55: 3792.2 | E55: Hold / No fresh trade | F55: 0.1843059 | G55: Hold / No fresh trade | H55: 0.27614069 | I55: Hold / No fresh trade | J55: 0.39558736 | K55: Down | L55: Down | M55: Sideways | N55: 83 | O55: -0.24156 | P55: ▼ Horizontal support breakdown (3+ touches) 09-Oct [weak edge]; ▼ Triple top 09-Oct [no edge] | Q55: Not checked
A56: CUMMINSIND | B56: Cummins India Ltd. | C56: Industrial Manufacturing | D56: 4344.2 | E56: Hold / No fresh trade | F56: 0.17962269 | G56: Hold / No fresh trade | H56: 0.27606879 | I56: Hold / No fresh trade | J56: 0.35499055 | K56: Down | L56: Down | M56: Sideways | N56: 51 | O56: -0.28783607 | P56: ▼ P&F double-bottom sell 23-Oct [works in reverse]; ▲ Wyckoff spring 22-Oct [works in reverse]; ▲ Bullish Wolfe wave 19-Oct [no edge] | Q56: Not checked
A57: GRAVITA | B57: Gravita India Ltd. | C57: Metals | D57: 1343.2 | E57: Hold / No fresh trade | F57: 0.17962269 | G57: Hold / No fresh trade | H57: 0.29501647 | I57: Hold / No fresh trade | J57: 0.37136452 | K57: Down | L57: Down | M57: Down | N57: 22 | O57: -0.29807692 | P57: ▼ Wave-3 / ABC breakdown 22-Oct [no edge]; ▲ 2B bottom / Turtle soup 21-Oct [no edge]; ▼ P&F bearish descending breakdown 21-Oct [works in reverse] | Q57: Not checked
... A314: GODREJCP | B314: Godrej Consumer Products Ltd. | C314: Consumer Goods | D314: 856.35 | E314: Avoid (likely underperformer) | F314: 0.17962269 | G314: Hold / No fresh trade | H314: 0.27001717 | I314: Hold / No fresh trade | J314: 0.38248096 | K314: Down | L314: Down | M314: Down | N314: 14 | O314: -0.32777298 | P314: ▼ Bearish divergence (OBV) 16-Oct [no edge]; ▲ Hidden bullish divergence (OBV) 15-Oct [no edge]; ▲ Downtrend-line breakout 14-Oct [works in reverse] | Q314: Not checked
A315: M&M | B315: Mahindra & Mahindra Ltd. | C315: Automobile | D315: 2861.2 | E315: Avoid (likely underperformer) | F315: 0.16804434 | G315: Hold / No fresh trade | H315: 0.28474942 | I315: Hold / No fresh trade | J315: 0.31927523 | K315: Down | L315: Down | M315: Down | N315: 35 | O315: -0.25487642 | Q315: Not checked
A316: TMCV | B316: Tata Motors Ltd. (commercial vehicles) | C316: Automobile | D316: 396 | E316: Avoid (likely underperformer) | F316: 0.16804434 | G316: Hold / No fresh trade | H316: 0.29501647 | I316: Hold / No fresh trade | J316: 0.37136452 | K316: Down | L316: Down | M316: Sideways | N316: 56 | O316: -0.22200394 | P316: ▼ Hidden bearish divergence (MACD hist) 23-Oct [no edge]; ▼ Horizontal support breakdown (3+ touches) 23-Oct [weak edge]; ▼ Wave-3 / ABC breakdown 23-Oct [no edge] | Q316: Not checked
A317: MARUTI | B317: Maruti Suzuki India Ltd. | C317: Automobile | D317: 11230 | E317: Avoid (likely underperformer) | F317: 0.16804434 | G317: Hold / No fresh trade | H317: 0.29501647 | I317: Hold / No fresh trade | J317: 0.31927523 | K317: Down | L317: Down | M317: Down | N317: 16 | O317: -0.35348301 | P317: ▲ 2B bottom / Turtle soup 22-Oct [no edge]; ▼ Hidden bearish divergence (MACD hist) 21-Oct [no edge]; ▲ Bullish divergence (MACD hist) 15-Oct [no edge] | Q317: Not checked
A318: SUZLON | B318: Suzlon Energy Ltd. | C318: Industrial Manufacturing | D318: 37.4 | E318: Hold / No fresh trade | F318: 0.16804434 | G318: Hold / No fresh trade | H318: 0.25519244 | I318: Reduce / Avoid | J318: 0.30470688 | K318: Down | L318: Down | M318: Down | N318: 5 | O318: -0.39186993 | P318: ▼ Hidden bearish divergence (MACD hist) 23-Oct [no edge]; ▼ V-top (spike) 23-Oct [tends to fail]; ▼ Hidden bearish divergence (MFI) 21-Oct [no edge] | Q318: Not checked
A319: TRENT | B319: Trent Ltd. | C319: Consumer Goods | D319: 2727.5 | E319: Hold / No fresh trade | F319: 0.16804434 | G319: Hold / No fresh trade | H319: 0.25176674 | I319: Reduce / Avoid | J319: 0.36484408 | K319: Down | L319: Down | M319: Sideways | N319: 60 | O319: -0.19772333 | P319: ▼ Hidden bearish divergence (MACD hist) 22-Oct [no edge]; ▼ Hidden bearish divergence (RSI) 22-Oct [no edge]; ▼ Fibonacci 38-62% rally failure (downtrend) 19-Oct [works] | Q319: Not checked
...

Sheet Top Picks
A1: Every buy call per timeframe, the strongest 'avoid' flags, and the latest results where checked
A2: Buys: Strong Buy first, then by expected return. Latest quarterly results (Q1 FY27) were checked by web search on 27-Sep-2026 - context only. Levels use the rules on 'Read Me'; recheck the price at the open.
A4: Short term (up to 2 weeks) - all 29 buy calls
A5: # | B5: Symbol | C5: Company | D5: Call | E5: Buy confidence | F5: Average stock | G5: Chance of profit | H5: Expected return / trade | I5: Entry up to Rs | J5: Target Rs | K5: Stop Rs | L5: Max days | M5: Why | N5: Results check | O5: Results & news | P5: Source
A6: 1 | B6: JWL | C6: Jupiter Wagons Ltd. | D6: Strong Buy | E6: 0.21183931 | F6: 0.15396106 | G6: 0.42819519 | H6: 0.0018773479 | I6: 181.83 | J6: 198.72 | K6: 160.72 | L6: 10 | M6: AI model top 1% | N6: Not checked | O6: Not researched
